Workbook

Sheet PriceData
A1: No. | B1: Date | C1: FPT | D1: HPG | E1: SSI | F1: VCB | G1: MWG | H1: VHM | I1: VNINDEX | J1: Vietnam 1Y Bond Yield (%) | K1: Vietnam 2Y Bond Yield (%) | L1: Vietnam 3Y Bond Yield (%) | M1: Vietnam 10Y Bond Yield (%)
A2: 1 | B2: 31/12/2025 | C2: 95800 | D2: 26400 | E2: 30250 | F2: 57500 | G2: 88400 | H2: 124000 | I2: 1784.49 | J2: 3.069 | K2: 3.121 | L2: 3.177 | M2: 4.186
A3: 2 | B3: 26/12/2025 | C3: 92500 | D3: 26900 | E3: 30750 | F3: 57100 | G3: 87000 | H3: 110000 | I3: 1729.8 | J3: 3.066 | K3: 3.118 | L3: 3.174 | M3: 4.179
A4: 3 | B4: 19/12/2025 | C4: 93900 | D4: 26700 | E4: 30800 | F4: 57500 | G4: 82900 | H4: 101500 | I4: 1704.31 | J4: 3.071 | K4: 3.123 | L4: 3.18 | M4: 4.153
A5: 4 | B5: 46003 | C5: 93700 | D5: 26000 | E5: 28100 | F5: 56800 | G5: 78500 | H5: 94100 | I5: 1646.89 | J5: 3.059 | K5: 3.107 | L5: 3.174 | M5: 4.124
A6: 5 | B6: 45789 | C6: 96200 | D6: 27000 | E6: 28650 | F6: 58300 | G6: 85100 | H6: 107000 | I6: 1741.32 | J6: 3.047 | K6: 3.096 | L6: 3.162 | M6: 4.097
A7: 6 | B7: 28/11/2025 | C7: 83570 | D7: 26550 | E7: 29140 | F7: 57400 | G7: 79900 | H7: 102900 | I7: 1690.99 | J7: 3.004 | K7: 3.049 | L7: 3.125 | M7: 4.031
A8: 7 | B8: 21/11/2025 | C8: 86750 | D8: 27400 | E8: 30470 | F8: 59000 | G8: 80000 | H8: 99300 | I8: 1654.93 | J8: 3.004 | K8: 3.05 | L8: 3.126 | M8: 3.985
A9: 8 | B9: 14/11/2025 | C9: 86060 | D9: 26900 | E9: 31050 | F9: 60000 | G9: 81400 | H9: 93900 | I9: 1635.46 | J9: 2.983 | K9: 3.028 | L9: 3.093 | M9: 4.004
A10: 9 | B10: 45849 | C10: 86920 | D10: 26050 | E10: 29270 | F10: 59300 | G10: 76500 | H10: 92000 | I10: 1599.1 | J10: 2.938 | K10: 2.994 | L10: 3.076 | M10: 3.978
A11: 10 | B11: 31/10/2025 | C11: 89420 | D11: 26700 | E11: 30470 | F11: 59600 | G11: 82600 | H11: 99200 | I11: 1639.65 | J11: 2.933 | K11: 2.979 | L11: 3.054 | M11: 3.954
A12: 11 | B12: 24/10/2025 | C12: 84080 | D12: 26400 | E12: 31980 | F12: 59500 | G12: 85700 | H12: 114500 | I12: 1683.18 | J12: 2.933 | K12: 2.98 | L12: 3.056 | M12: 3.917
A13: 12 | B13: 17/10/2025 | C13: 75820 | D13: 28000 | E13: 36240 | F13: 61900 | G13: 84500 | H13: 116000 | I13: 1731.19 | J13: 2.892 | K13: 2.941 | L13: 3.018 | M13: 3.876
A14: 13 | B14: 45940 | C14: 82710 | D14: 29600 | E14: 36150 | F14: 64200 | G14: 82000 | H14: 123000 | I14: 1747.55 | J14: 2.872 | K14: 2.921 | L14: 2.992 | M14: 3.854
A15: 14 | B15: 45726 | C15: 80380 | D15: 27650 | E15: 33440 | F15: 61700 | G15: 77000 | H15: 100000 | I15: 1645.82 | J15: 2.854 | K15: 2.908 | L15: 2.977 | M15: 3.79
A16: 15 | B16: 26/09/2025 | C16: 83910 | D16: 28550 | E16: 33760 | F16: 41840 | G16: 77900 | H16: 99000 | I16: 1660.7 | J16: 2.838 | K16: 2.884 | L16: 2.953 | M16: 3.759
A17: 16 | B17: 19/09/2025 | C17: 88650 | D17: 29250 | E17: 27980 | F17: 41840 | G17: 78600 | H17: 101700 | I17: 1658.62 | J17: 2.819 | K17: 2.865 | L17: 2.937 | M17: 3.704
A18: 17 | B18: 46000 | C18: 87440 | D18: 30000 | E18: 29060 | F18: 43700 | G18: 79000 | H18: 105500 | I18: 1667.26 | J18: 2.811 | K18: 2.858 | L18: 2.932 | M18: 3.695
A19: 18 | B19: 45786 | C19: 88990 | D19: 28800 | E19: 28090 | F19: 44830 | G19: 75000 | H19: 100000 | I19: 1666.97 | J19: 2.799 | K19: 2.848 | L19: 2.923 | M19: 3.664
A20: 19 | B20: 29/08/2025 | C20: 87440 | D20: 27500 | E20: 29270 | F20: 45560 | G20: 78000 | H20: 104500 | I20: 1682.21 | J20: 2.782 | K20: 2.831 | L20: 2.886 | M20: 3.689
A21: 20 | B21: 22/08/2025 | C21: 85200 | D21: 26000 | E21: 24790 | F21: 42900 | G21: 70300 | H21: 98100 | I21: 1645.47 | J21: 2.687 | K21: 2.739 | L21: 2.79 | M21: 3.672
A22: 21 | B22: 15/08/2025 | C22: 87270 | D22: 28000 | E22: 25350 | F22: 42700 | G22: 70500 | H22: 94000 | I22: 1630 | J22: 2.634 | K22: 2.686 | L22: 2.741 | M22: 3.56
A23: 22 | B23: 45877 | C23: 90880 | D23: 28000 | E23: 24620 | F23: 40970 | G23: 72000 | H23: 95000 | I23: 1584.95 | J23: 2.547 | K23: 2.602 | L23: 2.681 | M23: 3.492
A24: 23 | B24: 45665 | C24: 92090 | D24: 25150 | E24: 23020 | F24: 39980 | G24: 65200 | H24: 90000 | I24: 1495.21 | J24: 2.489 | K24: 2.543 | L24: 2.615 | M24: 3.462
A25: 24 | B25: 25/07/2025 | C25: 95270 | D25: 26050 | E25: 23580 | F25: 41240 | G25: 70100 | H25: 92000 | I25: 1531.13 | J25: 2.458 | K25: 2.499 | L25: 2.575 | M25: 3.434
A26: 25 | B26: 18/07/2025 | C26: 107520 | D26: 25900 | E26: 22050 | F26: 41310 | G26: 63050 | H26: 94100 | I26: 1497.28 | J26: 2.413 | K26: 2.445 | L26: 2.515 | M26: 3.398
A27: 26 | B27: 45968 | C27: 108030 | D27: 26000 | E27: 20560 | F27: 40770 | G27: 60550 | H27: 86000 | I27: 1457.76 | J27: 2.409 | K27: 2.467 | L27: 2.55 | M27: 3.352
A28: 27 | B28: 45754 | C28: 104530 | D28: 23250 | E28: 17960 | F28: 38450 | G28: 59130 | H28: 76300 | I28: 1386.97 | J28: 2.327 | K28: 2.376 | L28: 2.455 | M28: 3.344
A29: 28 | B29: 27/06/2025 | C29: 100100 | D29: 22850 | E29: 17090 | F29: 37450 | G29: 58680 | H29: 76000 | I29: 1371.44 | J29: 2.319 | K29: 2.36 | L29: 2.429 | M29: 3.323
A30: 29 | B30: 20/06/2025 | C30: 99070 | D30: 20450 | E30: 16640 | F30: 37590 | G30: 57160 | H30: 71700 | I30: 1349.35 | J30: 2.316 | K30: 2.358 | L30: 2.42 | M30: 3.307
A31: 30 | B31: 13/06/2025 | C31: 98470 | D31: 20000 | E31: 16050 | F31: 37190 | G31: 56360 | H31: 70000 | I31: 1315.49 | J31: 2.279 | K31: 2.321 | L31: 2.38 | M31: 3.27
A32: 31 | B32: 45814 | C32: 97460 | D32: 19730 | E32: 16370 | F32: 37390 | G32: 53950 | H32: 76800 | I32: 1329.89 | J32: 2.281 | K32: 2.326 | L32: 2.386 | M32: 3.252
A35: No. | B35: Months | C35: Weekly Return (Price Appreciation/Depreciation) | J35: Carry Return (Weekly yield, excluding price fluctuations)
C36: FPT | D36: HPG | E36: SSI | F36: VCB | G36: MWG | H36: VHM | I36: VNINDEX | J36: Vietnam 1Y Bond Yield (%) | K36: Vietnam 2Y Bond Yield (%) | L36: Vietnam 3Y Bond Yield (%) | M36: Vietnam 10Y Bond Yield (%)
A37: 1 | B37: 12 | C37: =(C2-C3)/C3 -> 0.035675676 | D37: =(D2-D3)/D3 -> -0.018587361 | E37: =(E2-E3)/E3 -> -0.016260163 | F37: =(F2-F3)/F3 -> 0.0070052539 | G37: =(G2-G3)/G3 -> 0.016091954 | H37: =(H2-H3)/H3 -> 0.12727273 | I37: =(I2-I3)/I3 -> 0.031616372 | J37: =(1+J2/100)^(1/52)-1 -> 0.00058148594 | K37: =(1+K2/100)^(1/52)-1 -> 0.00059119142 | L37: =(1+L2/100)^(1/52)-1 -> 0.0006016381 | M37: =(1+M2/100)^(1/52)-1 -> 0.00078891829
A38: 2 | B38: 12 | C38: =(C3-C4)/C4 -> -0.014909478 | D38: =(D3-D4)/D4 -> 0.0074906367 | E38: =(E3-E4)/E4 -> -0.0016233766 | F38: =(F3-F4)/F4 -> -0.0069565217 | G38: =(G3-G4)/G4 -> 0.049457177 | H38: =(H3-H4)/H4 -> 0.083743842 | I38: =(I3-I4)/I4 -> 0.014956199 | J38: =(1+J3/100)^(1/52)-1 -> 0.00058092586 | K38: =(1+K3/100)^(1/52)-1 -> 0.00059063162 | L38: =(1+L3/100)^(1/52)-1 -> 0.0006010786 | M38: =(1+M3/100)^(1/52)-1 -> 0.00078762516
A39: 3 | B39: 12 | C39: =(C4-C5)/C5 -> 0.0021344717 | D39: =(D4-D5)/D5 -> 0.026923077 | E39: =(E4-E5)/E5 -> 0.096085409 | F39: =(F4-F5)/F5 -> 0.012323944 | G39: =(G4-G5)/G5 -> 0.056050955 | H39: =(H4-H5)/H5 -> 0.078639745 | I39: =(I4-I5)/I5 -> 0.034865717 | J39: =(1+J4/100)^(1/52)-1 -> 0.00058185931 | K39: =(1+K4/100)^(1/52)-1 -> 0.00059156461 | L39: =(1+L4/100)^(1/52)-1 -> 0.00060219759 | M39: =(1+M4/100)^(1/52)-1 -> 0.00078282136
A40: 4 | B40: 12 | C40: =(C5-C6)/C6 -> -0.025987526 | D40: =(D5-D6)/D6 -> -0.037037037 | E40: =(E5-E6)/E6 -> -0.019197208 | F40: =(F5-F6)/F6 -> -0.025728988 | G40: =(G5-G6)/G6 -> -0.077555817 | H40: =(H5-H6)/H6 -> -0.12056075 | I40: =(I5-I6)/I6 -> -0.054228976 | J40: =(1+J5/100)^(1/52)-1 -> 0.00057961895 | K40: =(1+K5/100)^(1/52)-1 -> 0.00058857887 | L40: =(1+L5/100)^(1/52)-1 -> 0.0006010786 | M40: =(1+M5/100)^(1/52)-1 -> 0.00077746189
A41: 5 | B41: 12 | C41: =(C6-C7)/C7 -> 0.15113079 | D41: =(D6-D7)/D7 -> 0.016949153 | E41: =(E6-E7)/E7 -> -0.016815374 | F41: =(F6-F7)/F7 -> 0.015679443 | G41: =(G6-G7)/G7 -> 0.065081352 | H41: =(H6-H7)/H7 -> 0.039844509 | I41: =(I6-I7)/I7 -> 0.02976363 | J41: =(1+J6/100)^(1/52)-1 -> 0.00057737833 | K41: =(1+K6/100)^(1/52)-1 -> 0.00058652592 | L41: =(1+L6/100)^(1/52)-1 -> 0.00059884043 | M41: =(1+M6/100)^(1/52)-1 -> 0.00077247072
A42: 6 | B42: 11 | C42: =(C7-C8)/C8 -> -0.036657061 | D42: =(D7-D8)/D8 -> -0.031021898 | E42: =(E7-E8)/E8 -> -0.043649491 | F42: =(F7-F8)/F8 -> -0.027118644 | G42: =(G7-G8)/G8 -> -0.00125 | H42: =(H7-H8)/H8 -> 0.036253776 | I42: =(I7-I8)/I8 -> 0.021789441 | J42: =(1+J7/100)^(1/52)-1 -> 0.00056934733 | K42: =(1+K7/100)^(1/52)-1 -> 0.00057775178 | L42: =(1+L7/100)^(1/52)-1 -> 0.00059193779 | M42: =(1+M7/100)^(1/52)-1 -> 0.00076026473
...
